Traceback (most recent call last):
  File "C:\Users\bliu\AppData\Local\Programs\Python\Python36-32\lib\site-packages\urllib3\connectionpool.py", line 600, in urlopen
    chunked=chunked)
  File "C:\Users\bliu\AppData\Local\Programs\Python\Python36-32\lib\site-packages\urllib3\connectionpool.py", line 343, in _make_request
    self._validate_conn(conn)
  File "C:\Users\bliu\AppData\Local\Programs\Python\Python36-32\lib\site-packages\urllib3\connectionpool.py", line 849, in _validate_conn
    conn.connect()
  File "C:\Users\bliu\AppData\Local\Programs\Python\Python36-32\lib\site-packages\urllib3\connection.py", line 356, in connect
    ssl_context=context)
  File "C:\Users\bliu\AppData\Local\Programs\Python\Python36-32\lib\site-packages\urllib3\util\ssl_.py", line 359, in ssl_wrap_socket
    return context.wrap_socket(sock, server_hostname=server_hostname)
  File "C:\Users\bliu\AppData\Local\Programs\Python\Python36-32\lib\ssl.py", line 407, in wrap_socket
    _context=self, _session=session)
  File "C:\Users\bliu\AppData\Local\Programs\Python\Python36-32\lib\ssl.py", line 814, in __init__
    self.do_handshake()
  File "C:\Users\bliu\AppData\Local\Programs\Python\Python36-32\lib\ssl.py", line 1068, in do_handshake
    self._sslobj.do_handshake()
  File "C:\Users\bliu\AppData\Local\Programs\Python\Python36-32\lib\ssl.py", line 689, in do_handshake
    self._sslobj.do_handshake()
ssl.SSLError: [SSL: CERTIFICATE_VERIFY_FAILED] certificate verify failed (_ssl.c:833)

During handling of the above exception, another exception occurred:

Traceback (most recent call last):
  File "C:\Users\bliu\AppData\Local\Programs\Python\Python36-32\lib\site-packages\requests\adapters.py", line 445, in send
    timeout=timeout
  File "C:\Users\bliu\AppData\Local\Programs\Python\Python36-32\lib\site-packages\urllib3\connectionpool.py", line 638, in urlopen
    _stacktrace=sys.exc_info()[2])
  File "C:\Users\bliu\AppData\Local\Programs\Python\Python36-32\lib\site-packages\urllib3\util\retry.py", line 398, in increment
    raise MaxRetryError(_pool, url, error or ResponseError(cause))
urllib3.exceptions.MaxRetryError: HTTPSConnectionPool(host='nineelevenmemorialstg.prod.acquia-sites.com', port=443): Max retries exceeded with url: /join/individual (Caused by SSLError(SSLError(1, '[SSL: CERTIFICATE_VERIFY_FAILED] certificate verify failed (_ssl.c:833)'),))

During handling of the above exception, another exception occurred:

Traceback (most recent call last):
  File "cssSelectorScraper1.py", line 8, in <module>
    r = requests.get("https://nineelevenmemorialstg.prod.acquia-sites.com/join/individual")
  File "C:\Users\bliu\AppData\Local\Programs\Python\Python36-32\lib\site-packages\requests\api.py", line 72, in get
    return request('get', url, params=params, **kwargs)
  File "C:\Users\bliu\AppData\Local\Programs\Python\Python36-32\lib\site-packages\requests\api.py", line 58, in request
    return session.request(method=method, url=url, **kwargs)
  File "C:\Users\bliu\AppData\Local\Programs\Python\Python36-32\lib\site-packages\requests\sessions.py", line 512, in request
    resp = self.send(prep, **send_kwargs)
  File "C:\Users\bliu\AppData\Local\Programs\Python\Python36-32\lib\site-packages\requests\sessions.py", line 622, in send
    r = adapter.send(request, **kwargs)
  File "C:\Users\bliu\AppData\Local\Programs\Python\Python36-32\lib\site-packages\requests\adapters.py", line 511, in send
    raise SSLError(e, request=request)
requests.exceptions.SSLError: HTTPSConnectionPool(host='nineelevenmemorialstg.prod.acquia-sites.com', port=443): Max retries exceeded with url: /join/individual (Caused by SSLError(SSLError(1, '[SSL: CERTIFICATE_VERIFY_FAILED] certificate verify failed (_ssl.c:833)'),))

C:\Users\bliu\workprojects\automationtests>python cssSelectorScraper1.py > stagingsiteerror.txt
Traceback (most recent call last):
  File "C:\Users\bliu\AppData\Local\Programs\Python\Python36-32\lib\site-packages\urllib3\connectionpool.py", line 600, in urlopen
    chunked=chunked)
  File "C:\Users\bliu\AppData\Local\Programs\Python\Python36-32\lib\site-packages\urllib3\connectionpool.py", line 343, in _make_request
    self._validate_conn(conn)
  File "C:\Users\bliu\AppData\Local\Programs\Python\Python36-32\lib\site-packages\urllib3\connectionpool.py", line 849, in _validate_conn
    conn.connect()
  File "C:\Users\bliu\AppData\Local\Programs\Python\Python36-32\lib\site-packages\urllib3\connection.py", line 356, in connect
    ssl_context=context)
  File "C:\Users\bliu\AppData\Local\Programs\Python\Python36-32\lib\site-packages\urllib3\util\ssl_.py", line 359, in ssl_wrap_socket
    return context.wrap_socket(sock, server_hostname=server_hostname)
  File "C:\Users\bliu\AppData\Local\Programs\Python\Python36-32\lib\ssl.py", line 407, in wrap_socket
    _context=self, _session=session)
  File "C:\Users\bliu\AppData\Local\Programs\Python\Python36-32\lib\ssl.py", line 814, in __init__
    self.do_handshake()
  File "C:\Users\bliu\AppData\Local\Programs\Python\Python36-32\lib\ssl.py", line 1068, in do_handshake
    self._sslobj.do_handshake()
  File "C:\Users\bliu\AppData\Local\Programs\Python\Python36-32\lib\ssl.py", line 689, in do_handshake
    self._sslobj.do_handshake()
ssl.SSLError: [SSL: CERTIFICATE_VERIFY_FAILED] certificate verify failed (_ssl.c:833)

During handling of the above exception, another exception occurred:

Traceback (most recent call last):
  File "C:\Users\bliu\AppData\Local\Programs\Python\Python36-32\lib\site-packages\requests\adapters.py", line 445, in send
    timeout=timeout
  File "C:\Users\bliu\AppData\Local\Programs\Python\Python36-32\lib\site-packages\urllib3\connectionpool.py", line 638, in urlopen
    _stacktrace=sys.exc_info()[2])
  File "C:\Users\bliu\AppData\Local\Programs\Python\Python36-32\lib\site-packages\urllib3\util\retry.py", line 398, in increment
    raise MaxRetryError(_pool, url, error or ResponseError(cause))
urllib3.exceptions.MaxRetryError: HTTPSConnectionPool(host='nineelevenmemorialstg.prod.acquia-sites.com', port=443): Max retries exceeded with url: /join/individual (Caused by SSLError(SSLError(1, '[SSL: CERTIFICATE_VERIFY_FAILED] certificate verify failed (_ssl.c:833)'),))

During handling of the above exception, another exception occurred:

Traceback (most recent call last):
  File "cssSelectorScraper1.py", line 8, in <module>
    r = requests.get("https://nineelevenmemorialstg.prod.acquia-sites.com/join/individual")
  File "C:\Users\bliu\AppData\Local\Programs\Python\Python36-32\lib\site-packages\requests\api.py", line 72, in get
    return request('get', url, params=params, **kwargs)
  File "C:\Users\bliu\AppData\Local\Programs\Python\Python36-32\lib\site-packages\requests\api.py", line 58, in request
    return session.request(method=method, url=url, **kwargs)
  File "C:\Users\bliu\AppData\Local\Programs\Python\Python36-32\lib\site-packages\requests\sessions.py", line 512, in request
    resp = self.send(prep, **send_kwargs)
  File "C:\Users\bliu\AppData\Local\Programs\Python\Python36-32\lib\site-packages\requests\sessions.py", line 622, in send
    r = adapter.send(request, **kwargs)
  File "C:\Users\bliu\AppData\Local\Programs\Python\Python36-32\lib\site-packages\requests\adapters.py", line 511, in send
    raise SSLError(e, request=request)
requests.exceptions.SSLError: HTTPSConnectionPool(host='nineelevenmemorialstg.prod.acquia-sites.com', port=443): Max retries exceeded with url: /join/individual (Caused by SSLError(SSLError(1, '[SSL: CERTIFICATE_VERIFY_FAILED] certificate verify failed (_ssl.c:833)'),))